<?xml version="1.0" encoding="utf-8"?>
<!-- This URDF was automatically created by SolidWorks to URDF Exporter! Originally created by Stephen Brawner (brawner@gmail.com) 
     Commit Version: 1.5.1-0-g916b5db  Build Version: 1.5.7152.31018
     For more information, please see http://wiki.ros.org/sw_urdf_exporter -->
<robot name="deepracer">

<!-- Links and Joints -->
  <link name="base_link" />
    
  <link name="chassis">
    <inertial>
      <origin
        xyz="0 0 0"
        rpy="0 0 0" />
      <mass
        value="5.0" />
      <inertia
        ixx="0.010609"
        ixy="0"
        ixz="0"
        iyy="0.050409"
        iyz="0"
        izz="0.05865" />
    </inertial>
    <!--<visual>
      <origin
        xyz="0 0 0"
        rpy="0 0 0" />
      <geometry>
        <mesh
          filename="package://pkg/meshes/deepracer/chassis.STL" />
      </geometry>
    </visual>-->
  </link>
  
  <joint name="base_link_joint" type="fixed">
    <origin xyz="0 0 0.023249" rpy="0 0 0" />
    <parent link="base_link" />
    <child link="chassis" />
  </joint>
  
  <link
    name="left_rear_wheel">
    <inertial>
      <origin
        xyz="0 0 0"
        rpy="0 0 0" />
      <mass
        value="0.34055" />
      <inertia
        ixx="0.00026046"
        ixy="0"
        ixz="0"
        iyy="0.00041226"
        iyz="0"
        izz="0.00026046" />
    </inertial>
    <visual>
      <origin
        xyz="0 0 0"
        rpy="0 0 0" />
      <geometry>
        <mesh
          filename="package://pkg/meshes/deepracer/left_rear_wheel.STL" />
      </geometry>
    </visual>
    <collision>
      <origin
        xyz="0 0 0"
        rpy="0 0 0" />
      <geometry>
        <mesh
          filename="package://pkg/meshes/deepracer/left_rear_wheel.STL" />
      </geometry>
    </collision>
  </link>
  
  <joint
    name="left_rear_wheel_joint"
    type="continuous">
    <origin
      xyz="-0.081663 0.08105 0.01575"
      rpy="0 0 0" />
    <parent
      link="chassis" />
    <child
      link="left_rear_wheel" />
    <axis
      xyz="0 1 0" />
    <limit
      effort="10"
      velocity="100" />
  </joint>
  
  
  <link
    name="right_rear_wheel">
    <inertial>
      <origin
        xyz="0 0 0"
        rpy="0 0 0" />
      <mass
        value="0.34055" />
      <inertia
        ixx="0.00026046"
        ixy="0"
        ixz="0"
        iyy="0.00041226"
        iyz="0"
        izz="0.00026046" />
    </inertial>
    <visual>
      <origin
        xyz="0 0 0"
        rpy="0 0 0" />
      <geometry>
        <mesh
          filename="package://pkg/meshes/deepracer/right_rear_wheel.STL" />
      </geometry>
    </visual>
    <collision>
      <origin
        xyz="0 0 0"
        rpy="0 0 0" />
      <geometry>
        <mesh
          filename="package://pkg/meshes/deepracer/right_rear_wheel.STL" />
      </geometry>
    </collision>
  </link>
  

  <joint
    name="right_rear_wheel_joint"
    type="continuous">
    <origin
      xyz="-0.081663 -0.08105 0.01575"
      rpy="0 0 0" />
    <parent
      link="chassis" />
    <child
      link="right_rear_wheel" />
    <axis
      xyz="0 1 0" />
    <limit
      effort="10"
      velocity="100" />
  </joint>
  
  
  <link
    name="left_steering_hinge">
    <inertial>
      <origin
        xyz="0 0 0"
        rpy="0 0 0" />
      <mass
        value="0.1" />
      <inertia
        ixx="4E-06"
        ixy="0"
        ixz="0"
        iyy="4E-06"
        iyz="0"
        izz="4E-06" />
      </inertial>
    <visual>
      <origin
        xyz="0 0 0"
        rpy="0 0 0" />
      <geometry>
        <mesh
          filename="package://pkg/meshes/deepracer/left_steering_hinge.STL" />
      </geometry>
    </visual>
  </link>
  
  <joint
    name="left_steering_hinge_joint"
    type="continuous">
    <origin
      xyz="0.082311 0.079601 0.011759"
      rpy="0 0 0" />
    <parent
      link="chassis" />
    <child
      link="left_steering_hinge" />
    <axis
      xyz="0 0 1" />
    <limit
      lower="-1"
      upper="1"
      effort="10"
      velocity="100" />
  </joint>
  
  
  <link
    name="left_front_wheel">
    <inertial>
      <origin
        xyz="0 0 0"
        rpy="0 0 0" />
      <mass
        value="0.34055" />
      <inertia
        ixx="0.00026046"
        ixy="0"
        ixz="0"
        iyy="0.00041226"
        iyz="0"
        izz="0.00026046" />
    </inertial>
    <visual>
      <origin
        xyz="0 0 0"
        rpy="0 0 0" />
      <geometry>
        <mesh
          filename="package://pkg/meshes/deepracer/left_front_wheel.STL" />
      </geometry>
    </visual>
    <collision>
      <origin
        xyz="0 0 0"
        rpy="0 0 0" />
      <geometry>
        <mesh
          filename="package://pkg/meshes/deepracer/left_front_wheel.STL" />
      </geometry>
    </collision>
  </link>
  
  <joint
    name="left_front_wheel_joint"
    type="continuous">
    <origin
      xyz="0 0 0"
      rpy="0 0 0" />
    <parent
      link="left_steering_hinge" />
    <child
      link="left_front_wheel" />
    <axis
      xyz="0 1 0" />
    <limit
      effort="10"
      velocity="100" />
  </joint>
  
  
  <link
    name="right_steering_hinge">
    <inertial>
      <origin
        xyz="0 0 0"
        rpy="0 0 0" />
      <mass
        value="0.1" />
      <inertia
        ixx="4E-06"
        ixy="0"
        ixz="0"
        iyy="4E-06"
        iyz="0"
        izz="4E-06" />
    </inertial>
    <visual>
      <origin
        xyz="0 0 0"
        rpy="0 0 0" />
      <geometry>
        <mesh
          filename="package://pkg/meshes/deepracer/right_steering_hinge.STL" />
      </geometry>
    </visual>
  </link>
  
  <joint
    name="right_steering_hinge_joint"
    type="continuous">
    <origin
      xyz="0.082311 -0.079601 0.011759"
      rpy="0 0 0" />
    <parent
      link="chassis" />
    <child
      link="right_steering_hinge" />
    <axis
      xyz="0 0 1" />
    <limit
      lower="-1"
      upper="1"
      effort="10"
      velocity="100" />
  </joint>
  <link
    name="right_front_wheel">
    <inertial>
      <origin
        xyz="0 0 0"
        rpy="0 0 0" />
      <mass
        value="0.34055" />
      <inertia
        ixx="0.00026046"
        ixy="0"
        ixz="0"
        iyy="0.00041226"
        iyz="0"
        izz="0.00026046" />
    </inertial>
    <visual>
      <origin
        xyz="0 0 0"
        rpy="0 0 0" />
      <geometry>
        <mesh
          filename="package://pkg/meshes/deepracer/right_front_wheel.STL" />
      </geometry>
    </visual>
    <collision>
      <origin
        xyz="0 0 0"
        rpy="0 0 0" />
      <geometry>
        <mesh
          filename="package://pkg/meshes/deepracer/right_front_wheel.STL" />
      </geometry>
    </collision>
  </link>
  
  <joint
    name="right_front_wheel_joint"
    type="continuous">
    <origin
      xyz="0 0 0"
      rpy="0 0 0" />
    <parent
      link="right_steering_hinge" />
    <child
      link="right_front_wheel" />
    <axis
      xyz="0 1 0" />
    <limit
      effort="10"
      velocity="100" />
  </joint>
  
  <link
    name="zed_camera_link_leftcam">
    <inertial>
      <origin
        xyz="0.019881 6.2875E-05 0.034966"
        rpy="0 0 0" />
      <mass
        value="1e-3" />
      <inertia 
        ixx="1e-6"
        ixy="0"
        ixz="0"
        iyy="1e-6"
        iyz="0"
        izz="1e-6" />
    </inertial>
    <visual>
      <origin
        xyz="0 0 0"
        rpy="0 0 0" />
      <geometry>
        <mesh
          filename="package://pkg/meshes/deepracer/zed_camera_link_leftcam.STL" />
      </geometry>
    </visual>
  </link>
  
  <joint
    name="zed_camera_joint_leftcam"
    type="fixed">
    <origin
      xyz="0.091711 0.03 0.080023"
      rpy="0 0.2618 0" />
    <parent
      link="chassis" />
    <child
      link="zed_camera_link_leftcam" />
    <axis
      xyz="0 0 0" />
  </joint>
  <link
    name="camera_link_leftcam">
    <inertial>
      <origin
        xyz="0.0005 0 0"
        rpy="0 0 0" />
      <mass
        value="1e-3" />
      <inertia 
        ixx="1e-6"
        ixy="0"
        ixz="0"
        iyy="1e-6"
        iyz="0"
        izz="1e-6" />
    </inertial>
<!--     <visual>
      <origin
        xyz="0 0 0"
        rpy="0 0 0" />
      <geometry>
        <mesh
          filename="package://pkg/meshes/deepracer/camera_link_leftcam.STL" />
      </geometry>
    </visual> -->
  </link>
  <joint
    name="camera_joint_leftcam"
    type="fixed">
    <origin
      xyz="0.044755 0 0.04"
      rpy="0 0 0" />
    <parent
      link="zed_camera_link_leftcam" />
    <child
      link="camera_link_leftcam" />
    <axis
      xyz="0 0 0" />
  </joint>
  <link
    name="zed_camera_link_rightcam">
    <inertial>
      <origin
        xyz="0.019881 6.2895E-05 0.034966"
        rpy="0 0 0" />
      <mass
        value="1e-3" />
      <inertia 
        ixx="1e-6"
        ixy="0"
        ixz="0"
        iyy="1e-6"
        iyz="0"
        izz="1e-6" />
    </inertial>
    <visual>
      <origin
        xyz="0 0 0"
        rpy="0 0 0" />
      <geometry>
        <mesh
          filename="package://pkg/meshes/deepracer/zed_camera_link_rightcam.STL" />
      </geometry>
    </visual>
  </link>

  <joint
    name="zed_camera_joint_rightcam"
    type="fixed">
    <origin
      xyz="0.091711 -0.03 0.080023"
      rpy="0 0.2618 0" />
    <parent
      link="chassis" />
    <child
      link="zed_camera_link_rightcam" />
    <axis
      xyz="0 0 0" />
  </joint>
  <link
    name="camera_link_rightcam">
    <inertial>
      <origin
        xyz="0.0005 0 0"
        rpy="0 0 0" />
      <mass
        value="1e-3" />
      <inertia 
        ixx="1e-6"
        ixy="0"
        ixz="0"
        iyy="1e-6"
        iyz="0"
        izz="1e-6" />
    </inertial>
<!--     <visual>
      <origin
        xyz="0 0 0"
        rpy="0 0 0" />
      <geometry>
        <mesh
          filename="package://pkg/meshes/deepracer/camera_link_rightcam.STL" />
      </geometry>
    </visual> -->
  </link>

  <joint
    name="camera_joint_rightcam"
    type="fixed">
    <origin
      xyz="0.044755 0 0.04"
      rpy="0 0 0" />
    <parent
      link="zed_camera_link_rightcam" />
    <child
      link="camera_link_rightcam" />
    <axis
      xyz="0 0 0" />
  </joint>
  <link
    name="laser">
    <inertial>
      <origin
        xyz="0.006099 0.00028423 -0.012654"
        rpy="0 0 0" />
      <mass
        value="1E-5" />
      <inertia
        ixx="1e-6"
        ixy="0"
        ixz="0"
        iyy="1e-6"
        iyz="0"
        izz="1e-6" />
    </inertial>
    <visual>
      <origin
        xyz="0 0 0"
        rpy="0 0 0" />
      <geometry>
        <mesh
          filename="package://pkg/meshes/deepracer/laser.STL" />
      </geometry>
    </visual>
    <collision>
      <origin
        xyz="0 0 0"
        rpy="0 0 0" />
      <geometry>
        <mesh
          filename="package://pkg/meshes/deepracer/laser.STL" />
      </geometry>
    </collision>
  </link>

  <joint
    name="hokuyo_joint"
    type="fixed">
    <origin
      xyz="0.02913 0 0.16145" 
      rpy="0 0 3.1416" />
    <parent
      link="chassis" />
    <child
      link="laser" />
    <axis
      xyz="0 0 0" />
  </joint>
  <link
    name="car_body_link_v3">
    <inertial>
      <origin
        xyz="0 0 0"
        rpy="0 0 0" />
      <mass
        value="0" />
      <inertia
        ixx="0"
        ixy="0"
        ixz="0"
        iyy="0"
        iyz="0"
        izz="0" />
    </inertial>
    <visual>
      <origin
        xyz="0 0 0"
        rpy="0 0 0" />
      <geometry>
        <mesh
          filename="package://pkg/meshes/deepracer/car_body_link_lidar_v3.STL" />
      </geometry>
    </visual>
    <collision>
      <origin
        xyz="0 0 0"
        rpy="0 0 0" />
      <geometry>
        <mesh
          filename="package://pkg/meshes/deepracer/car_body_link_lidar_v3.STL" />
      </geometry>
    </collision>
  </link>

  <joint
    name="car_body_joint"
    type="fixed">
    <origin
      xyz="-0.0762 0 2E-05"
      rpy="0 0 0" />
    <parent
      link="chassis" />
    <child
      link="car_body_link_v3" />
    <axis
      xyz="0 0 0" />
  </joint>
  
<!-- Gazebo Tags -->

<!-- Vehicle body -->
  <gazebo reference = "chassis">
   <material>Gazebo/Grey</material>
   <mu1 value="0.0"/>
   <mu2 value="0.0"/>
   <kp  value="1000000.0" />
  </gazebo>
  <gazebo reference = "left_rear_wheel">
   <material>Gazebo/DarkGrey</material>
   <mu1 value="0.5"/>
   <mu2 value="0.5"/>
   <kp  value="1000000.0" />
   <kd  value="1.0" />
   <fdir1 value="1 0 0"/>
  </gazebo>
  <gazebo reference = "left_front_wheel">
   <material>Gazebo/DarkGrey</material>
   <mu1 value="0.5"/>
   <mu2 value="0.5"/>
   <kp  value="1000000.0" />
   <kd  value="1.0" />
   <fdir1 value="1 0 0"/>
  </gazebo>
  <gazebo reference = "right_rear_wheel">
   <material>Gazebo/DarkGrey</material>
   <mu1 value="0.5"/>
   <mu2 value="0.5"/>
   <kp  value="1000000.0" />
   <kd  value="1.0" />
   <fdir1 value="1 0 0"/>
  </gazebo>
  <gazebo reference = "right_front_wheel">
   <material>Gazebo/DarkGrey</material>
   <mu1 value="0.5"/>
   <mu2 value="0.5"/>
   <kp  value="1000000.0" />
   <kd  value="1.0" />
   <fdir1 value="1 0 0"/>
  </gazebo>
  <gazebo reference = "left_steering_hinge">
   <material>Gazebo/DarkGrey</material>
  </gazebo>
  <gazebo reference = "right_steering_hinge">
   <material>Gazebo/DarkGrey</material>
  </gazebo>
  <gazebo reference = "zed_camera_link_leftcam">
   <material>Gazebo/DarkGrey</material>
  </gazebo>
  <gazebo reference = "zed_camera_link_rightcam">
   <material>Gazebo/DarkGrey</material>
  </gazebo>
  <gazebo reference = "laser">
   <material>Gazebo/DarkGrey</material>
  </gazebo>
  <gazebo reference = "car_body_link_v3">
   <material>Gazebo/Grey</material>
  </gazebo>
  
<!-- Chassis Controller-->
    <gazebo>
      <plugin name='gazebo_ros_deepracer_drive' filename='libgazebo_ros_deepracer_drive.so'>
        
        <update_rate>15.0</update_rate>

        <!-- Max absolute steer angle for tyre in radians-->
        <!-- Any cmd_vel angular z greater than this would be capped -->
        <max_steer>0.523599</max_steer>

        <!-- Max absolute linear speed in m/s -->
        <max_speed>4</max_speed> 
        
        <!-- Radius of rear wheels, in meters -->
        <wheel_radius>0.03</wheel_radius>
        <!-- Distance between front and rear axles, in meters -->
        <wheel_base>0.164023</wheel_base>
        <!-- Distance between the wheels, in meters -->
        <wheel_separation>0.159202</wheel_separation>

        <publish_odom>true</publish_odom>
        <publish_odom_tf>true</publish_odom_tf>

        <odometry_frame>odom</odometry_frame>
        <robot_base_frame>base_link</robot_base_frame>
	
      </plugin>
  </gazebo>
  
<!-- Stere Cameras -->
  <gazebo reference="camera_link_leftcam">
    <material>Gazebo/White</material>
    <sensor type="camera" name="zed_camera_left_sensor">
      <pose>0 0 0 0 0 0</pose>
      <update_rate>10</update_rate>
      <camera name="zed_camera_left_camera">
        <horizontal_fov>1.13</horizontal_fov>
        <image>
          <width>640</width>
          <height>480</height>
          <format>R8G8B8</format>
        </image>
        <clip>
          <near>0.02</near>
          <far>300</far>
        </clip>
      </camera>
      <plugin name="camera_controller" filename="libgazebo_ros_camera.so">
        <alwaysOn>true</alwaysOn>
        <!-- Turn down if virtual machine-->
        <updateRate>10</updateRate>
        <cameraName>deepracer/camera/zed_left</cameraName>
        <imageTopicName>image_rect_color_left</imageTopicName>
        <cameraInfoTopicName>camera_info_left</cameraInfoTopicName>
        <frameName>camera_link_left</frameName>
        <hackBaseline>0.12</hackBaseline><!-- set this to 0.12 for the second camera -->
        <distortionK1>0.0</distortionK1>
        <distortionK2>0.0</distortionK2>
        <distortionK3>0.0</distortionK3>
        <distortionT1>0.0</distortionT1>
        <distortionT2>0.0</distortionT2>
      </plugin>
    </sensor>
  </gazebo>

  <gazebo reference="camera_link_rightcam">
    <material>Gazebo/White</material>
    <sensor type="camera" name="zed_camera_right_sensor">
      <pose>0 0 0 0 0 0</pose>
      <update_rate>10</update_rate>
      <camera name="zed_camera_right_camera">
        <horizontal_fov>1.13</horizontal_fov>
        <image>
          <width>640</width>
          <height>480</height>
          <format>R8G8B8</format>
        </image>
        <clip>
          <near>0.02</near>
          <far>300</far>
        </clip>
      </camera>
      <plugin name="camera_controller_right" filename="libgazebo_ros_camera.so">
        <alwaysOn>true</alwaysOn>
        <!-- Turn down if virtual machine-->
        <updateRate>10</updateRate>
        <cameraName>deepracer/camera/zed_right</cameraName>
        <imageTopicName>image_rect_color_right</imageTopicName>
        <cameraInfoTopicName>camera_info_right</cameraInfoTopicName>
        <frameName>camera_link_right</frameName>
        <hackBaseline>0.0</hackBaseline>
        <distortionK1>0.0</distortionK1>
        <distortionK2>0.0</distortionK2>
        <distortionK3>0.0</distortionK3>
        <distortionT1>0.0</distortionT1>
        <distortionT2>0.0</distortionT2>
      </plugin>
    </sensor>
  </gazebo>

<!-- Laser Radar -->
  <gazebo reference="laser">
    <sensor type="ray" name="hokuyo_sensor">
      <pose>0 0 0 0 0 0</pose>
      <visualize>true</visualize>
      <update_rate>10</update_rate>
      <ray>
        <scan>
          <horizontal>
            <samples>600</samples>
            <resolution>1</resolution>
            <min_angle>-2.61799</min_angle>
            <max_angle>2.61799</max_angle>
          </horizontal>
        </scan>
        <range>
          <min>0.15</min>
          <max>10</max>
          <resolution>0.01</resolution>
        </range>
        <noise>
          <mean>0.0</mean>
          <stddev>0.01</stddev>
        </noise>
      </ray>

       <plugin name="rp_lidar" filename="libgazebo_ros_ray_sensor.so">
          <ros>
            <argument>~/out:=scan</argument>
          </ros>
          <output_type>sensor_msgs/LaserScan</output_type>
          <frame_name>laser</frame_name>
        </plugin>
    </sensor>
  </gazebo>
  
</robot>